{"format":"kwatch-observations","version":1,"start":"2026-09-29T10:00:00Z"}
{"at":"2026-09-29T10:00:00Z","obs":{"kind":"observed","source":"kubernetes","at":"2026-09-29T10:00:00Z","entity":{"kind":"node","name":"w1"},"uid":"3aad064e2af7de5a","attributes":{"condition.Ready":{"text":"True"},"condition.Ready.reason":{"text":"KubeletReady"},"condition.Ready.since":{"time":"2026-09-29T09:00:00Z"},"cpu.allocatable":{"number":4000},"deleting":{"bool":false},"instance.type":{"text":""},"kernel.version":{"text":""},"kubelet.version":{"text":""},"memory.allocatable":{"number":17179869184},"os":{"text":""},"ready":{"bool":true},"ready.transition":{"time":"2026-09-29T09:00:00Z"},"runtime.version":{"text":""},"taints":{"text":""},"unschedulable":{"bool":false}}}}
{"at":"2026-09-29T10:00:00Z","obs":{"kind":"related","source":"kubernetes","at":"2026-09-29T10:00:00Z","entity":{"kind":"node","name":"w1"},"relation":"part-of","targets":[{"kind":"zone","name":"zone-a"}]}}
{"at":"2026-09-29T10:00:00Z","obs":{"kind":"observed","source":"kubernetes","at":"2026-09-29T10:00:00Z","entity":{"kind":"node","name":"w2"},"uid":"0aba7238a7dc6533","attributes":{"condition.Ready":{"text":"True"},"condition.Ready.reason":{"text":"KubeletReady"},"condition.Ready.since":{"time":"2026-09-29T09:00:00Z"},"cpu.allocatable":{"number":4000},"deleting":{"bool":false},"instance.type":{"text":""},"kernel.version":{"text":""},"kubelet.version":{"text":""},"memory.allocatable":{"number":17179869184},"os":{"text":""},"ready":{"bool":true},"ready.transition":{"time":"2026-09-29T09:00:00Z"},"runtime.version":{"text":""},"taints":{"text":""},"unschedulable":{"bool":false}}}}
{"at":"2026-09-29T10:00:00Z","obs":{"kind":"related","source":"kubernetes","at":"2026-09-29T10:00:00Z","entity":{"kind":"node","name":"w2"},"relation":"part-of","targets":[{"kind":"zone","name":"zone-a"}]}}
{"at":"2026-09-29T10:00:00Z","obs":{"kind":"observed","source":"kubernetes","at":"2026-09-29T10:00:00Z","entity":{"kind":"node","name":"w3"},"uid":"c2e51a223687f71d","attributes":{"condition.Ready":{"text":"True"},"condition.Ready.reason":{"text":"KubeletReady"},"condition.Ready.since":{"time":"2026-09-29T09:00:00Z"},"cpu.allocatable":{"number":4000},"deleting":{"bool":false},"instance.type":{"text":""},"kernel.version":{"text":""},"kubelet.version":{"text":""},"memory.allocatable":{"number":17179869184},"os":{"text":""},"ready":{"bool":true},"ready.transition":{"time":"2026-09-29T09:00:00Z"},"runtime.version":{"text":""},"taints":{"text":""},"unschedulable":{"bool":false}}}}
{"at":"2026-09-29T10:00:00Z","obs":{"kind":"related","source":"kubernetes","at":"2026-09-29T10:00:00Z","entity":{"kind":"node","name":"w3"},"relation":"part-of","targets":[{"kind":"zone","name":"zone-a"}]}}
{"at":"2026-09-29T10:00:00Z","obs":{"kind":"observed","source":"kubernetes","at":"2026-09-29T10:00:00Z","entity":{"kind":"node","name":"w4"},"uid":"6008af5b2608cce2","attributes":{"condition.Ready":{"text":"True"},"condition.Ready.reason":{"text":"KubeletReady"},"condition.Ready.since":{"time":"2026-09-29T09:00:00Z"},"cpu.allocatable":{"number":4000},"deleting":{"bool":false},"instance.type":{"text":""},"kernel.version":{"text":""},"kubelet.version":{"text":""},"memory.allocatable":{"number":17179869184},"os":{"text":""},"ready":{"bool":true},"ready.transition":{"time":"2026-09-29T09:00:00Z"},"runtime.version":{"text":""},"taints":{"text":""},"unschedulable":{"bool":false}}}}
{"at":"2026-09-29T10:00:00Z","obs":{"kind":"related","source":"kubernetes","at":"2026-09-29T10:00:00Z","entity":{"kind":"node","name":"w4"},"relation":"part-of","targets":[{"kind":"zone","name":"zone-a"}]}}
{"at":"2026-09-29T10:00:00Z","obs":{"kind":"observed","source":"kubernetes","at":"2026-09-29T10:00:00Z","entity":{"kind":"node","name":"cp1"},"uid":"099fb42f2ec965c3","attributes":{"condition.Ready":{"text":"True"},"condition.Ready.reason":{"text":"KubeletReady"},"condition.Ready.since":{"time":"2026-09-29T09:00:00Z"},"cpu.allocatable":{"number":4000},"deleting":{"bool":false},"instance.type":{"text":""},"kernel.version":{"text":""},"kubelet.version":{"text":""},"memory.allocatable":{"number":17179869184},"os":{"text":""},"ready":{"bool":true},"ready.transition":{"time":"2026-09-29T09:00:00Z"},"runtime.version":{"text":""},"taints":{"text":"node-role.kubernetes.io/control-plane:NoSchedule"},"unschedulable":{"bool":false}}}}
{"at":"2026-09-29T10:00:00Z","obs":{"kind":"related","source":"kubernetes","at":"2026-09-29T10:00:00Z","entity":{"kind":"node","name":"cp1"},"relation":"part-of","targets":[{"kind":"zone","name":"zone-a"}]}}
{"at":"2026-09-29T10:00:00Z","obs":{"kind":"observed","source":"kubernetes","at":"2026-09-29T10:00:00Z","entity":{"kind":"node","name":"cp2"},"uid":"bed62de2d13efe74","attributes":{"condition.Ready":{"text":"True"},"condition.Ready.reason":{"text":"KubeletReady"},"condition.Ready.since":{"time":"2026-09-29T09:00:00Z"},"cpu.allocatable":{"number":4000},"deleting":{"bool":false},"instance.type":{"text":""},"kernel.version":{"text":""},"kubelet.version":{"text":""},"memory.allocatable":{"number":17179869184},"os":{"text":""},"ready":{"bool":true},"ready.transition":{"time":"2026-09-29T09:00:00Z"},"runtime.version":{"text":""},"taints":{"text":"node-role.kubernetes.io/control-plane:NoSchedule"},"unschedulable":{"bool":false}}}}
{"at":"2026-09-29T10:00:00Z","obs":{"kind":"related","source":"kubernetes","at":"2026-09-29T10:00:00Z","entity":{"kind":"node","name":"cp2"},"relation":"part-of","targets":[{"kind":"zone","name":"zone-a"}]}}
{"at":"2026-09-29T10:00:00Z","obs":{"kind":"observed","source":"kubernetes","at":"2026-09-29T10:00:00Z","entity":{"kind":"deployment","namespace":"analytics","name":"etl"},"uid":"8c7bd424c6f9b587","attributes":{"deleting":{"bool":false},"generation":{"number":1},"generation.observed":{"number":1},"replicas":{"number":2},"replicas.available":{"number":2},"replicas.ready":{"number":2},"replicas.unavailable":{"number":0},"replicas.updated":{"number":2},"template.hash":{"text":"2b2f2b5b823c"}}}}
{"at":"2026-09-29T10:00:00Z","obs":{"kind":"related","source":"kubernetes","at":"2026-09-29T10:00:00Z","entity":{"kind":"deployment","namespace":"analytics","name":"etl"},"relation":"owned-by"}}
{"at":"2026-09-29T10:00:00Z","obs":{"kind":"related","source":"kubernetes","at":"2026-09-29T10:00:00Z","entity":{"kind":"deployment","namespace":"analytics","name":"etl"},"relation":"references"}}
{"at":"2026-09-29T10:00:00Z","obs":{"kind":"observed","source":"kubernetes","at":"2026-09-29T10:00:00Z","entity":{"kind":"replicaset","namespace":"analytics","name":"etl-23a8b2cd"},"uid":"etl-23a8b2cd","attributes":{"deleting":{"bool":false},"generation":{"number":0},"generation.observed":{"number":0},"replicas":{"number":2},"replicas.available":{"number":2},"replicas.ready":{"number":2},"template.hash":{"text":"2b2f2b5b823c"}}}}
{"at":"2026-09-29T10:00:00Z","obs":{"kind":"related","source":"kubernetes","at":"2026-09-29T10:00:00Z","entity":{"kind":"replicaset","namespace":"analytics","name":"etl-23a8b2cd"},"relation":"owned-by","targets":[{"kind":"deployment","namespace":"analytics","name":"etl"}]}}
{"at":"2026-09-29T10:00:00Z","obs":{"kind":"related","source":"kubernetes","at":"2026-09-29T10:00:00Z","entity":{"kind":"replicaset","namespace":"analytics","name":"etl-23a8b2cd"},"relation":"references"}}
{"at":"2026-09-29T10:00:00Z","obs":{"kind":"observed","source":"kubernetes","at":"2026-09-29T10:00:00Z","entity":{"kind":"pod","namespace":"analytics","name":"etl-23a8b2cd-a"},"uid":"etl-23a8b2cd-a","attributes":{"condition.ContainersReady":{"text":"True"},"condition.ContainersReady.since":{"time":"2026-09-29T09:00:00Z"},"condition.PodScheduled":{"text":"True"},"condition.PodScheduled.since":{"time":"2026-09-29T09:00:00Z"},"condition.Ready":{"text":"True"},"condition.Ready.since":{"time":"2026-09-29T09:00:00Z"},"created":{"time":"2026-09-29T09:00:00Z"},"deleting":{"bool":false},"labels":{"text":"app=etl"},"phase":{"text":"Running"},"qos":{"text":"Burstable"},"ready":{"bool":true},"ready.transition":{"time":"2026-09-29T09:00:00Z"},"start.time":{"time":"2026-09-29T09:00:00Z"}}}}
{"at":"2026-09-29T10:00:00Z","obs":{"kind":"related","source":"kubernetes","at":"2026-09-29T10:00:00Z","entity":{"kind":"pod","namespace":"analytics","name":"etl-23a8b2cd-a"},"relation":"mounts"}}
{"at":"2026-09-29T10:00:00Z","obs":{"kind":"related","source":"kubernetes","at":"2026-09-29T10:00:00Z","entity":{"kind":"pod","namespace":"analytics","name":"etl-23a8b2cd-a"},"relation":"owned-by","targets":[{"kind":"replicaset","namespace":"analytics","name":"etl-23a8b2cd"}]}}
{"at":"2026-09-29T10:00:00Z","obs":{"kind":"related","source":"kubernetes","at":"2026-09-29T10:00:00Z","entity":{"kind":"pod","namespace":"analytics","name":"etl-23a8b2cd-a"},"relation":"pulls","targets":[{"kind":"image","name":"registry.example.com/etl:4.1"}]}}
{"at":"2026-09-29T10:00:00Z","obs":{"kind":"related","source":"kubernetes","at":"2026-09-29T10:00:00Z","entity":{"kind":"pod","namespace":"analytics","name":"etl-23a8b2cd-a"},"relation":"references"}}
{"at":"2026-09-29T10:00:00Z","obs":{"kind":"related","source":"kubernetes","at":"2026-09-29T10:00:00Z","entity":{"kind":"pod","namespace":"analytics","name":"etl-23a8b2cd-a"},"relation":"runs-on","targets":[{"kind":"node","name":"w1"}]}}
{"at":"2026-09-29T10:00:00Z","obs":{"kind":"observed","source":"kubernetes","at":"2026-09-29T10:00:00Z","entity":{"kind":"container","namespace":"analytics","name":"etl-23a8b2cd-a/app"},"attributes":{"image":{"text":"registry.example.com/etl:4.1"},"init":{"bool":false},"ready":{"bool":true},"restarts":{"number":0},"sidecar":{"bool":false},"started.at":{"time":"2026-09-29T09:00:00Z"},"state":{"text":"running"}}}}
{"at":"2026-09-29T10:00:00Z","obs":{"kind":"related","source":"kubernetes","at":"2026-09-29T10:00:00Z","entity":{"kind":"container","namespace":"analytics","name":"etl-23a8b2cd-a/app"},"relation":"part-of","targets":[{"kind":"pod","namespace":"analytics","name":"etl-23a8b2cd-a"}]}}
{"at":"2026-09-29T10:00:00Z","obs":{"kind":"related","source":"kubernetes","at":"2026-09-29T10:00:00Z","entity":{"kind":"container","namespace":"analytics","name":"etl-23a8b2cd-a/app"},"relation":"pulls","targets":[{"kind":"image","name":"registry.example.com/etl:4.1"}]}}
{"at":"2026-09-29T10:00:00Z","obs":{"kind":"observed","source":"kubernetes","at":"2026-09-29T10:00:00Z","entity":{"kind":"pod","namespace":"analytics","name":"etl-23a8b2cd-b"},"uid":"etl-23a8b2cd-b","attributes":{"condition.ContainersReady":{"text":"True"},"condition.ContainersReady.since":{"time":"2026-09-29T09:00:00Z"},"condition.PodScheduled":{"text":"True"},"condition.PodScheduled.since":{"time":"2026-09-29T09:00:00Z"},"condition.Ready":{"text":"True"},"condition.Ready.since":{"time":"2026-09-29T09:00:00Z"},"created":{"time":"2026-09-29T09:00:00Z"},"deleting":{"bool":false},"labels":{"text":"app=etl"},"phase":{"text":"Running"},"qos":{"text":"Burstable"},"ready":{"bool":true},"ready.transition":{"time":"2026-09-29T09:00:00Z"},"start.time":{"time":"2026-09-29T09:00:00Z"}}}}
{"at":"2026-09-29T10:00:00Z","obs":{"kind":"related","source":"kubernetes","at":"2026-09-29T10:00:00Z","entity":{"kind":"pod","namespace":"analytics","name":"etl-23a8b2cd-b"},"relation":"mounts"}}
{"at":"2026-09-29T10:00:00Z","obs":{"kind":"related","source":"kubernetes","at":"2026-09-29T10:00:00Z","entity":{"kind":"pod","namespace":"analytics","name":"etl-23a8b2cd-b"},"relation":"owned-by","targets":[{"kind":"replicaset","namespace":"analytics","name":"etl-23a8b2cd"}]}}
{"at":"2026-09-29T10:00:00Z","obs":{"kind":"related","source":"kubernetes","at":"2026-09-29T10:00:00Z","entity":{"kind":"pod","namespace":"analytics","name":"etl-23a8b2cd-b"},"relation":"pulls","targets":[{"kind":"image","name":"registry.example.com/etl:4.1"}]}}
{"at":"2026-09-29T10:00:00Z","obs":{"kind":"related","source":"kubernetes","at":"2026-09-29T10:00:00Z","entity":{"kind":"pod","namespace":"analytics","name":"etl-23a8b2cd-b"},"relation":"references"}}
{"at":"2026-09-29T10:00:00Z","obs":{"kind":"related","source":"kubernetes","at":"2026-09-29T10:00:00Z","entity":{"kind":"pod","namespace":"analytics","name":"etl-23a8b2cd-b"},"relation":"runs-on","targets":[{"kind":"node","name":"w2"}]}}
{"at":"2026-09-29T10:00:00Z","obs":{"kind":"observed","source":"kubernetes","at":"2026-09-29T10:00:00Z","entity":{"kind":"container","namespace":"analytics","name":"etl-23a8b2cd-b/app"},"attributes":{"image":{"text":"registry.example.com/etl:4.1"},"init":{"bool":false},"ready":{"bool":true},"restarts":{"number":0},"sidecar":{"bool":false},"started.at":{"time":"2026-09-29T09:00:00Z"},"state":{"text":"running"}}}}
{"at":"2026-09-29T10:00:00Z","obs":{"kind":"related","source":"kubernetes","at":"2026-09-29T10:00:00Z","entity":{"kind":"container","namespace":"analytics","name":"etl-23a8b2cd-b/app"},"relation":"part-of","targets":[{"kind":"pod","namespace":"analytics","name":"etl-23a8b2cd-b"}]}}
{"at":"2026-09-29T10:00:00Z","obs":{"kind":"related","source":"kubernetes","at":"2026-09-29T10:00:00Z","entity":{"kind":"container","namespace":"analytics","name":"etl-23a8b2cd-b/app"},"relation":"pulls","targets":[{"kind":"image","name":"registry.example.com/etl:4.1"}]}}
{"at":"2026-09-29T10:01:00Z","obs":{"kind":"observed","source":"kubernetes","at":"2026-09-29T10:01:00Z","entity":{"kind":"deployment","namespace":"analytics","name":"etl"},"uid":"8c7bd424c6f9b587","attributes":{"deleting":{"bool":false},"generation":{"number":2},"generation.observed":{"number":2},"replicas":{"number":5},"replicas.available":{"number":2},"replicas.ready":{"number":2},"replicas.unavailable":{"number":3},"replicas.updated":{"number":5},"template.hash":{"text":"2b2f2b5b823c"}}}}
{"at":"2026-09-29T10:01:00Z","obs":{"kind":"related","source":"kubernetes","at":"2026-09-29T10:01:00Z","entity":{"kind":"deployment","namespace":"analytics","name":"etl"},"relation":"owned-by"}}
{"at":"2026-09-29T10:01:00Z","obs":{"kind":"related","source":"kubernetes","at":"2026-09-29T10:01:00Z","entity":{"kind":"deployment","namespace":"analytics","name":"etl"},"relation":"references"}}
{"at":"2026-09-29T10:01:00Z","obs":{"kind":"changed","source":"kubernetes","at":"2026-09-29T10:01:00Z","entity":{"kind":"deployment","namespace":"analytics","name":"etl"},"change":{"at":"2026-09-29T10:01:00Z","observed":"2026-09-29T10:01:00Z","revision":"generation 2","fields":[{"path":"spec.replicas","before":"2","after":"5"}]}}}
{"at":"2026-09-29T10:01:00Z","obs":{"kind":"observed","source":"kubernetes","at":"2026-09-29T10:01:00Z","entity":{"kind":"replicaset","namespace":"analytics","name":"etl-23a8b2cd"},"uid":"etl-23a8b2cd","attributes":{"deleting":{"bool":false},"generation":{"number":0},"generation.observed":{"number":0},"replicas":{"number":5},"replicas.available":{"number":2},"replicas.ready":{"number":2},"template.hash":{"text":"2b2f2b5b823c"}}}}
{"at":"2026-09-29T10:01:00Z","obs":{"kind":"related","source":"kubernetes","at":"2026-09-29T10:01:00Z","entity":{"kind":"replicaset","namespace":"analytics","name":"etl-23a8b2cd"},"relation":"owned-by","targets":[{"kind":"deployment","namespace":"analytics","name":"etl"}]}}
{"at":"2026-09-29T10:01:00Z","obs":{"kind":"related","source":"kubernetes","at":"2026-09-29T10:01:00Z","entity":{"kind":"replicaset","namespace":"analytics","name":"etl-23a8b2cd"},"relation":"references"}}
{"at":"2026-09-29T10:01:00Z","obs":{"kind":"changed","source":"kubernetes","at":"2026-09-29T10:01:00Z","entity":{"kind":"replicaset","namespace":"analytics","name":"etl-23a8b2cd"},"change":{"at":"2026-09-29T10:01:00Z","observed":"2026-09-29T10:01:00Z","fields":[{"path":"spec.replicas","before":"2","after":"5"}]}}}
{"at":"2026-09-29T10:01:00Z","obs":{"kind":"observed","source":"kubernetes","at":"2026-09-29T10:01:00Z","entity":{"kind":"pod","namespace":"analytics","name":"etl-23a8b2cd-c"},"uid":"etl-23a8b2cd-c","attributes":{"condition.PodScheduled":{"text":"False"},"condition.PodScheduled.message":{"text":"0/6 nodes are available: 4 Insufficient memory, 2 node(s) had untolerated taint {node-role.kubernetes.io/control-plane: }. preemption: 0/6 nodes are available: 2 Preemption is not helpful for scheduling, 4 No preemption victims found for incoming pod."},"condition.PodScheduled.reason":{"text":"Unschedulable"},"condition.PodScheduled.since":{"time":"2026-09-29T10:01:00Z"},"created":{"time":"2026-09-29T10:01:00Z"},"deleting":{"bool":false},"labels":{"text":"app=etl"},"phase":{"text":"Pending"},"qos":{"text":"Burstable"}}}}
{"at":"2026-09-29T10:01:00Z","obs":{"kind":"related","source":"kubernetes","at":"2026-09-29T10:01:00Z","entity":{"kind":"pod","namespace":"analytics","name":"etl-23a8b2cd-c"},"relation":"mounts"}}
{"at":"2026-09-29T10:01:00Z","obs":{"kind":"related","source":"kubernetes","at":"2026-09-29T10:01:00Z","entity":{"kind":"pod","namespace":"analytics","name":"etl-23a8b2cd-c"},"relation":"owned-by","targets":[{"kind":"replicaset","namespace":"analytics","name":"etl-23a8b2cd"}]}}
{"at":"2026-09-29T10:01:00Z","obs":{"kind":"related","source":"kubernetes","at":"2026-09-29T10:01:00Z","entity":{"kind":"pod","namespace":"analytics","name":"etl-23a8b2cd-c"},"relation":"pulls","targets":[{"kind":"image","name":"registry.example.com/etl:4.1"}]}}
{"at":"2026-09-29T10:01:00Z","obs":{"kind":"related","source":"kubernetes","at":"2026-09-29T10:01:00Z","entity":{"kind":"pod","namespace":"analytics","name":"etl-23a8b2cd-c"},"relation":"references"}}
{"at":"2026-09-29T10:01:00Z","obs":{"kind":"related","source":"kubernetes","at":"2026-09-29T10:01:00Z","entity":{"kind":"pod","namespace":"analytics","name":"etl-23a8b2cd-c"},"relation":"runs-on"}}
{"at":"2026-09-29T10:01:00Z","obs":{"kind":"observed","source":"kubernetes","at":"2026-09-29T10:01:00Z","entity":{"kind":"container","namespace":"analytics","name":"etl-23a8b2cd-c/app"},"attributes":{"image":{"text":"registry.example.com/etl:4.1"},"init":{"bool":false},"sidecar":{"bool":false}}}}
{"at":"2026-09-29T10:01:00Z","obs":{"kind":"related","source":"kubernetes","at":"2026-09-29T10:01:00Z","entity":{"kind":"container","namespace":"analytics","name":"etl-23a8b2cd-c/app"},"relation":"part-of","targets":[{"kind":"pod","namespace":"analytics","name":"etl-23a8b2cd-c"}]}}
{"at":"2026-09-29T10:01:00Z","obs":{"kind":"related","source":"kubernetes","at":"2026-09-29T10:01:00Z","entity":{"kind":"container","namespace":"analytics","name":"etl-23a8b2cd-c/app"},"relation":"pulls","targets":[{"kind":"image","name":"registry.example.com/etl:4.1"}]}}
{"at":"2026-09-29T10:01:00Z","obs":{"kind":"changed","source":"kubernetes","at":"2026-09-29T10:01:00Z","entity":{"kind":"pod","namespace":"analytics","name":"etl-23a8b2cd-c"},"change":{"at":"2026-09-29T10:01:00Z","observed":"2026-09-29T10:01:00Z","created":true}}}
{"at":"2026-09-29T10:01:00Z","obs":{"kind":"observed","source":"kubernetes","at":"2026-09-29T10:01:00Z","entity":{"kind":"pod","namespace":"analytics","name":"etl-23a8b2cd-d"},"uid":"etl-23a8b2cd-d","attributes":{"condition.PodScheduled":{"text":"False"},"condition.PodScheduled.message":{"text":"0/6 nodes are available: 4 Insufficient memory, 2 node(s) had untolerated taint {node-role.kubernetes.io/control-plane: }. preemption: 0/6 nodes are available: 2 Preemption is not helpful for scheduling, 4 No preemption victims found for incoming pod."},"condition.PodScheduled.reason":{"text":"Unschedulable"},"condition.PodScheduled.since":{"time":"2026-09-29T10:01:00Z"},"created":{"time":"2026-09-29T10:01:00Z"},"deleting":{"bool":false},"labels":{"text":"app=etl"},"phase":{"text":"Pending"},"qos":{"text":"Burstable"}}}}
{"at":"2026-09-29T10:01:00Z","obs":{"kind":"related","source":"kubernetes","at":"2026-09-29T10:01:00Z","entity":{"kind":"pod","namespace":"analytics","name":"etl-23a8b2cd-d"},"relation":"mounts"}}
{"at":"2026-09-29T10:01:00Z","obs":{"kind":"related","source":"kubernetes","at":"2026-09-29T10:01:00Z","entity":{"kind":"pod","namespace":"analytics","name":"etl-23a8b2cd-d"},"relation":"owned-by","targets":[{"kind":"replicaset","namespace":"analytics","name":"etl-23a8b2cd"}]}}
{"at":"2026-09-29T10:01:00Z","obs":{"kind":"related","source":"kubernetes","at":"2026-09-29T10:01:00Z","entity":{"kind":"pod","namespace":"analytics","name":"etl-23a8b2cd-d"},"relation":"pulls","targets":[{"kind":"image","name":"registry.example.com/etl:4.1"}]}}
{"at":"2026-09-29T10:01:00Z","obs":{"kind":"related","source":"kubernetes","at":"2026-09-29T10:01:00Z","entity":{"kind":"pod","namespace":"analytics","name":"etl-23a8b2cd-d"},"relation":"references"}}
{"at":"2026-09-29T10:01:00Z","obs":{"kind":"related","source":"kubernetes","at":"2026-09-29T10:01:00Z","entity":{"kind":"pod","namespace":"analytics","name":"etl-23a8b2cd-d"},"relation":"runs-on"}}
{"at":"2026-09-29T10:01:00Z","obs":{"kind":"observed","source":"kubernetes","at":"2026-09-29T10:01:00Z","entity":{"kind":"container","namespace":"analytics","name":"etl-23a8b2cd-d/app"},"attributes":{"image":{"text":"registry.example.com/etl:4.1"},"init":{"bool":false},"sidecar":{"bool":false}}}}
{"at":"2026-09-29T10:01:00Z","obs":{"kind":"related","source":"kubernetes","at":"2026-09-29T10:01:00Z","entity":{"kind":"container","namespace":"analytics","name":"etl-23a8b2cd-d/app"},"relation":"part-of","targets":[{"kind":"pod","namespace":"analytics","name":"etl-23a8b2cd-d"}]}}
{"at":"2026-09-29T10:01:00Z","obs":{"kind":"related","source":"kubernetes","at":"2026-09-29T10:01:00Z","entity":{"kind":"container","namespace":"analytics","name":"etl-23a8b2cd-d/app"},"relation":"pulls","targets":[{"kind":"image","name":"registry.example.com/etl:4.1"}]}}
{"at":"2026-09-29T10:01:00Z","obs":{"kind":"changed","source":"kubernetes","at":"2026-09-29T10:01:00Z","entity":{"kind":"pod","namespace":"analytics","name":"etl-23a8b2cd-d"},"change":{"at":"2026-09-29T10:01:00Z","observed":"2026-09-29T10:01:00Z","created":true}}}
{"at":"2026-09-29T10:01:00Z","obs":{"kind":"observed","source":"kubernetes","at":"2026-09-29T10:01:00Z","entity":{"kind":"pod","namespace":"analytics","name":"etl-23a8b2cd-e"},"uid":"etl-23a8b2cd-e","attributes":{"condition.PodScheduled":{"text":"False"},"condition.PodScheduled.message":{"text":"0/6 nodes are available: 4 Insufficient memory, 2 node(s) had untolerated taint {node-role.kubernetes.io/control-plane: }. preemption: 0/6 nodes are available: 2 Preemption is not helpful for scheduling, 4 No preemption victims found for incoming pod."},"condition.PodScheduled.reason":{"text":"Unschedulable"},"condition.PodScheduled.since":{"time":"2026-09-29T10:01:00Z"},"created":{"time":"2026-09-29T10:01:00Z"},"deleting":{"bool":false},"labels":{"text":"app=etl"},"phase":{"text":"Pending"},"qos":{"text":"Burstable"}}}}
{"at":"2026-09-29T10:01:00Z","obs":{"kind":"related","source":"kubernetes","at":"2026-09-29T10:01:00Z","entity":{"kind":"pod","namespace":"analytics","name":"etl-23a8b2cd-e"},"relation":"mounts"}}
{"at":"2026-09-29T10:01:00Z","obs":{"kind":"related","source":"kubernetes","at":"2026-09-29T10:01:00Z","entity":{"kind":"pod","namespace":"analytics","name":"etl-23a8b2cd-e"},"relation":"owned-by","targets":[{"kind":"replicaset","namespace":"analytics","name":"etl-23a8b2cd"}]}}
{"at":"2026-09-29T10:01:00Z","obs":{"kind":"related","source":"kubernetes","at":"2026-09-29T10:01:00Z","entity":{"kind":"pod","namespace":"analytics","name":"etl-23a8b2cd-e"},"relation":"pulls","targets":[{"kind":"image","name":"registry.example.com/etl:4.1"}]}}
{"at":"2026-09-29T10:01:00Z","obs":{"kind":"related","source":"kubernetes","at":"2026-09-29T10:01:00Z","entity":{"kind":"pod","namespace":"analytics","name":"etl-23a8b2cd-e"},"relation":"references"}}
{"at":"2026-09-29T10:01:00Z","obs":{"kind":"related","source":"kubernetes","at":"2026-09-29T10:01:00Z","entity":{"kind":"pod","namespace":"analytics","name":"etl-23a8b2cd-e"},"relation":"runs-on"}}
{"at":"2026-09-29T10:01:00Z","obs":{"kind":"observed","source":"kubernetes","at":"2026-09-29T10:01:00Z","entity":{"kind":"container","namespace":"analytics","name":"etl-23a8b2cd-e/app"},"attributes":{"image":{"text":"registry.example.com/etl:4.1"},"init":{"bool":false},"sidecar":{"bool":false}}}}
{"at":"2026-09-29T10:01:00Z","obs":{"kind":"related","source":"kubernetes","at":"2026-09-29T10:01:00Z","entity":{"kind":"container","namespace":"analytics","name":"etl-23a8b2cd-e/app"},"relation":"part-of","targets":[{"kind":"pod","namespace":"analytics","name":"etl-23a8b2cd-e"}]}}
{"at":"2026-09-29T10:01:00Z","obs":{"kind":"related","source":"kubernetes","at":"2026-09-29T10:01:00Z","entity":{"kind":"container","namespace":"analytics","name":"etl-23a8b2cd-e/app"},"relation":"pulls","targets":[{"kind":"image","name":"registry.example.com/etl:4.1"}]}}
{"at":"2026-09-29T10:01:00Z","obs":{"kind":"changed","source":"kubernetes","at":"2026-09-29T10:01:00Z","entity":{"kind":"pod","namespace":"analytics","name":"etl-23a8b2cd-e"},"change":{"at":"2026-09-29T10:01:00Z","observed":"2026-09-29T10:01:00Z","created":true}}}
{"at":"2026-09-29T10:02:00Z","obs":{"kind":"noted","source":"kubernetes","at":"2026-09-29T10:02:00Z","entity":{"kind":"pod","namespace":"analytics","name":"etl-23a8b2cd-c"},"note":{"at":"2026-09-29T10:02:00Z","source":"default-scheduler","reason":"FailedScheduling","message":"0/6 nodes are available: 4 Insufficient memory, 2 node(s) had untolerated taint {node-role.kubernetes.io/control-plane: }. preemption: 0/6 nodes are available: 2 Preemption is not helpful for scheduling, 4 No preemption victims found for incoming pod.","count":1,"warning":true}}}
{"at":"2026-09-29T10:02:00Z","obs":{"kind":"noted","source":"kubernetes","at":"2026-09-29T10:02:00Z","entity":{"kind":"pod","namespace":"analytics","name":"etl-23a8b2cd-d"},"note":{"at":"2026-09-29T10:02:00Z","source":"default-scheduler","reason":"FailedScheduling","message":"0/6 nodes are available: 4 Insufficient memory, 2 node(s) had untolerated taint {node-role.kubernetes.io/control-plane: }. preemption: 0/6 nodes are available: 2 Preemption is not helpful for scheduling, 4 No preemption victims found for incoming pod.","count":1,"warning":true}}}
{"at":"2026-09-29T10:02:00Z","obs":{"kind":"noted","source":"kubernetes","at":"2026-09-29T10:02:00Z","entity":{"kind":"pod","namespace":"analytics","name":"etl-23a8b2cd-e"},"note":{"at":"2026-09-29T10:02:00Z","source":"default-scheduler","reason":"FailedScheduling","message":"0/6 nodes are available: 4 Insufficient memory, 2 node(s) had untolerated taint {node-role.kubernetes.io/control-plane: }. preemption: 0/6 nodes are available: 2 Preemption is not helpful for scheduling, 4 No preemption victims found for incoming pod.","count":1,"warning":true}}}
{"at":"2026-09-29T10:03:00Z","obs":{"kind":"noted","source":"kubernetes","at":"2026-09-29T10:03:00Z","entity":{"kind":"pod","namespace":"analytics","name":"etl-23a8b2cd-c"},"note":{"at":"2026-09-29T10:03:00Z","source":"default-scheduler","reason":"FailedScheduling","message":"0/6 nodes are available: 4 Insufficient memory, 2 node(s) had untolerated taint {node-role.kubernetes.io/control-plane: }. preemption: 0/6 nodes are available: 2 Preemption is not helpful for scheduling, 4 No preemption victims found for incoming pod.","count":2,"warning":true}}}
{"at":"2026-09-29T10:03:00Z","obs":{"kind":"noted","source":"kubernetes","at":"2026-09-29T10:03:00Z","entity":{"kind":"pod","namespace":"analytics","name":"etl-23a8b2cd-d"},"note":{"at":"2026-09-29T10:03:00Z","source":"default-scheduler","reason":"FailedScheduling","message":"0/6 nodes are available: 4 Insufficient memory, 2 node(s) had untolerated taint {node-role.kubernetes.io/control-plane: }. preemption: 0/6 nodes are available: 2 Preemption is not helpful for scheduling, 4 No preemption victims found for incoming pod.","count":2,"warning":true}}}
{"at":"2026-09-29T10:03:00Z","obs":{"kind":"noted","source":"kubernetes","at":"2026-09-29T10:03:00Z","entity":{"kind":"pod","namespace":"analytics","name":"etl-23a8b2cd-e"},"note":{"at":"2026-09-29T10:03:00Z","source":"default-scheduler","reason":"FailedScheduling","message":"0/6 nodes are available: 4 Insufficient memory, 2 node(s) had untolerated taint {node-role.kubernetes.io/control-plane: }. preemption: 0/6 nodes are available: 2 Preemption is not helpful for scheduling, 4 No preemption victims found for incoming pod.","count":2,"warning":true}}}
{"at":"2026-09-29T10:04:00Z","obs":{"kind":"noted","source":"kubernetes","at":"2026-09-29T10:04:00Z","entity":{"kind":"pod","namespace":"analytics","name":"etl-23a8b2cd-c"},"note":{"at":"2026-09-29T10:04:00Z","source":"default-scheduler","reason":"FailedScheduling","message":"0/6 nodes are available: 4 Insufficient memory, 2 node(s) had untolerated taint {node-role.kubernetes.io/control-plane: }. preemption: 0/6 nodes are available: 2 Preemption is not helpful for scheduling, 4 No preemption victims found for incoming pod.","count":3,"warning":true}}}
{"at":"2026-09-29T10:04:00Z","obs":{"kind":"noted","source":"kubernetes","at":"2026-09-29T10:04:00Z","entity":{"kind":"pod","namespace":"analytics","name":"etl-23a8b2cd-d"},"note":{"at":"2026-09-29T10:04:00Z","source":"default-scheduler","reason":"FailedScheduling","message":"0/6 nodes are available: 4 Insufficient memory, 2 node(s) had untolerated taint {node-role.kubernetes.io/control-plane: }. preemption: 0/6 nodes are available: 2 Preemption is not helpful for scheduling, 4 No preemption victims found for incoming pod.","count":3,"warning":true}}}
{"at":"2026-09-29T10:04:00Z","obs":{"kind":"noted","source":"kubernetes","at":"2026-09-29T10:04:00Z","entity":{"kind":"pod","namespace":"analytics","name":"etl-23a8b2cd-e"},"note":{"at":"2026-09-29T10:04:00Z","source":"default-scheduler","reason":"FailedScheduling","message":"0/6 nodes are available: 4 Insufficient memory, 2 node(s) had untolerated taint {node-role.kubernetes.io/control-plane: }. preemption: 0/6 nodes are available: 2 Preemption is not helpful for scheduling, 4 No preemption victims found for incoming pod.","count":3,"warning":true}}}
{"at":"2026-09-29T10:05:00Z","obs":{"kind":"noted","source":"kubernetes","at":"2026-09-29T10:05:00Z","entity":{"kind":"pod","namespace":"analytics","name":"etl-23a8b2cd-c"},"note":{"at":"2026-09-29T10:05:00Z","source":"default-scheduler","reason":"FailedScheduling","message":"0/6 nodes are available: 4 Insufficient memory, 2 node(s) had untolerated taint {node-role.kubernetes.io/control-plane: }. preemption: 0/6 nodes are available: 2 Preemption is not helpful for scheduling, 4 No preemption victims found for incoming pod.","count":4,"warning":true}}}
{"at":"2026-09-29T10:05:00Z","obs":{"kind":"noted","source":"kubernetes","at":"2026-09-29T10:05:00Z","entity":{"kind":"pod","namespace":"analytics","name":"etl-23a8b2cd-d"},"note":{"at":"2026-09-29T10:05:00Z","source":"default-scheduler","reason":"FailedScheduling","message":"0/6 nodes are available: 4 Insufficient memory, 2 node(s) had untolerated taint {node-role.kubernetes.io/control-plane: }. preemption: 0/6 nodes are available: 2 Preemption is not helpful for scheduling, 4 No preemption victims found for incoming pod.","count":4,"warning":true}}}
{"at":"2026-09-29T10:05:00Z","obs":{"kind":"noted","source":"kubernetes","at":"2026-09-29T10:05:00Z","entity":{"kind":"pod","namespace":"analytics","name":"etl-23a8b2cd-e"},"note":{"at":"2026-09-29T10:05:00Z","source":"default-scheduler","reason":"FailedScheduling","message":"0/6 nodes are available: 4 Insufficient memory, 2 node(s) had untolerated taint {node-role.kubernetes.io/control-plane: }. preemption: 0/6 nodes are available: 2 Preemption is not helpful for scheduling, 4 No preemption victims found for incoming pod.","count":4,"warning":true}}}
{"at":"2026-09-29T10:06:00Z","obs":{"kind":"noted","source":"kubernetes","at":"2026-09-29T10:06:00Z","entity":{"kind":"pod","namespace":"analytics","name":"etl-23a8b2cd-c"},"note":{"at":"2026-09-29T10:06:00Z","source":"default-scheduler","reason":"FailedScheduling","message":"0/6 nodes are available: 4 Insufficient memory, 2 node(s) had untolerated taint {node-role.kubernetes.io/control-plane: }. preemption: 0/6 nodes are available: 2 Preemption is not helpful for scheduling, 4 No preemption victims found for incoming pod.","count":5,"warning":true}}}
{"at":"2026-09-29T10:06:00Z","obs":{"kind":"noted","source":"kubernetes","at":"2026-09-29T10:06:00Z","entity":{"kind":"pod","namespace":"analytics","name":"etl-23a8b2cd-d"},"note":{"at":"2026-09-29T10:06:00Z","source":"default-scheduler","reason":"FailedScheduling","message":"0/6 nodes are available: 4 Insufficient memory, 2 node(s) had untolerated taint {node-role.kubernetes.io/control-plane: }. preemption: 0/6 nodes are available: 2 Preemption is not helpful for scheduling, 4 No preemption victims found for incoming pod.","count":5,"warning":true}}}
{"at":"2026-09-29T10:06:00Z","obs":{"kind":"noted","source":"kubernetes","at":"2026-09-29T10:06:00Z","entity":{"kind":"pod","namespace":"analytics","name":"etl-23a8b2cd-e"},"note":{"at":"2026-09-29T10:06:00Z","source":"default-scheduler","reason":"FailedScheduling","message":"0/6 nodes are available: 4 Insufficient memory, 2 node(s) had untolerated taint {node-role.kubernetes.io/control-plane: }. preemption: 0/6 nodes are available: 2 Preemption is not helpful for scheduling, 4 No preemption victims found for incoming pod.","count":5,"warning":true}}}
