{"format":"kwatch-observations","version":1,"start":"2026-09-29T10:00:00Z"}
{"at":"2026-09-29T10:00:00Z","obs":{"kind":"observed","source":"kubernetes","at":"2026-09-29T10:00:00Z","entity":{"kind":"node","name":"n1"},"uid":"432d4db310fd0a0d","attributes":{"condition.Ready":{"text":"True"},"condition.Ready.reason":{"text":"KubeletReady"},"condition.Ready.since":{"time":"2026-09-29T09:00:00Z"},"cpu.allocatable":{"number":4000},"created":{"time":"2026-09-28T10:00:00Z"},"deleting":{"bool":false},"instance.type":{"text":""},"kernel.version":{"text":""},"kubelet.version":{"text":""},"memory.allocatable":{"number":17179869184},"os":{"text":""},"ready":{"bool":true},"ready.transition":{"time":"2026-09-29T09:00:00Z"},"runtime.version":{"text":""},"taints":{"text":""},"unschedulable":{"bool":false}}}}
{"at":"2026-09-29T10:00:00Z","obs":{"kind":"related","source":"kubernetes","at":"2026-09-29T10:00:00Z","entity":{"kind":"node","name":"n1"},"relation":"part-of","targets":[{"kind":"zone","name":"zone-a"}]}}
{"at":"2026-09-29T10:00:00Z","obs":{"kind":"observed","source":"kubernetes","at":"2026-09-29T10:00:00Z","entity":{"kind":"node","name":"n2"},"uid":"28f8c5780aa8a382","attributes":{"condition.Ready":{"text":"True"},"condition.Ready.reason":{"text":"KubeletReady"},"condition.Ready.since":{"time":"2026-09-29T09:00:00Z"},"cpu.allocatable":{"number":4000},"created":{"time":"2026-09-28T10:00:00Z"},"deleting":{"bool":false},"instance.type":{"text":""},"kernel.version":{"text":""},"kubelet.version":{"text":""},"memory.allocatable":{"number":17179869184},"os":{"text":""},"ready":{"bool":true},"ready.transition":{"time":"2026-09-29T09:00:00Z"},"runtime.version":{"text":""},"taints":{"text":""},"unschedulable":{"bool":false}}}}
{"at":"2026-09-29T10:00:00Z","obs":{"kind":"related","source":"kubernetes","at":"2026-09-29T10:00:00Z","entity":{"kind":"node","name":"n2"},"relation":"part-of","targets":[{"kind":"zone","name":"zone-a"}]}}
{"at":"2026-09-29T10:00:00Z","obs":{"kind":"observed","source":"kubernetes","at":"2026-09-29T10:00:00Z","entity":{"kind":"node","name":"n3"},"uid":"1c461d7006eed2b8","attributes":{"condition.Ready":{"text":"True"},"condition.Ready.reason":{"text":"KubeletReady"},"condition.Ready.since":{"time":"2026-09-29T09:00:00Z"},"cpu.allocatable":{"number":4000},"created":{"time":"2026-09-28T10:00:00Z"},"deleting":{"bool":false},"instance.type":{"text":""},"kernel.version":{"text":""},"kubelet.version":{"text":""},"memory.allocatable":{"number":17179869184},"os":{"text":""},"ready":{"bool":true},"ready.transition":{"time":"2026-09-29T09:00:00Z"},"runtime.version":{"text":""},"taints":{"text":""},"unschedulable":{"bool":false}}}}
{"at":"2026-09-29T10:00:00Z","obs":{"kind":"related","source":"kubernetes","at":"2026-09-29T10:00:00Z","entity":{"kind":"node","name":"n3"},"relation":"part-of","targets":[{"kind":"zone","name":"zone-a"}]}}
{"at":"2026-09-29T10:00:00Z","obs":{"kind":"observed","source":"kubernetes","at":"2026-09-29T10:00:00Z","entity":{"kind":"deployment","namespace":"batch","name":"filler"},"uid":"54feda80bf7cc68d","attributes":{"created":{"time":"2026-09-28T10:00:00Z"},"deleting":{"bool":false},"generation":{"number":2},"generation.observed":{"number":2},"replicas":{"number":3},"replicas.available":{"number":3},"replicas.ready":{"number":3},"replicas.unavailable":{"number":0},"replicas.updated":{"number":3},"template.hash":{"text":"3bd5f5d5b7e5"},"template.labels":{"text":"app=filler"}}}}
{"at":"2026-09-29T10:00:00Z","obs":{"kind":"related","source":"kubernetes","at":"2026-09-29T10:00:00Z","entity":{"kind":"deployment","namespace":"batch","name":"filler"},"relation":"owned-by"}}
{"at":"2026-09-29T10:00:00Z","obs":{"kind":"related","source":"kubernetes","at":"2026-09-29T10:00:00Z","entity":{"kind":"deployment","namespace":"batch","name":"filler"},"relation":"references"}}
{"at":"2026-09-29T10:00:00Z","obs":{"kind":"observed","source":"kubernetes","at":"2026-09-29T10:00:00Z","entity":{"kind":"replicaset","namespace":"batch","name":"filler-852d2550"},"uid":"filler-852d2550","attributes":{"created":{"time":"2026-09-29T10:00:00Z"},"deleting":{"bool":false},"generation":{"number":0},"generation.observed":{"number":0},"replicas":{"number":3},"replicas.available":{"number":3},"replicas.ready":{"number":3},"template.hash":{"text":"3bd5f5d5b7e5"},"template.labels":{"text":"app=filler"}}}}
{"at":"2026-09-29T10:00:00Z","obs":{"kind":"related","source":"kubernetes","at":"2026-09-29T10:00:00Z","entity":{"kind":"replicaset","namespace":"batch","name":"filler-852d2550"},"relation":"owned-by","targets":[{"kind":"deployment","namespace":"batch","name":"filler"}]}}
{"at":"2026-09-29T10:00:00Z","obs":{"kind":"related","source":"kubernetes","at":"2026-09-29T10:00:00Z","entity":{"kind":"replicaset","namespace":"batch","name":"filler-852d2550"},"relation":"references"}}
{"at":"2026-09-29T10:00:00Z","obs":{"kind":"observed","source":"kubernetes","at":"2026-09-29T10:00:00Z","entity":{"kind":"pod","namespace":"batch","name":"filler-852d2550-a"},"uid":"filler-852d2550-a","attributes":{"condition.ContainersReady":{"text":"True"},"condition.ContainersReady.since":{"time":"2026-09-29T09:00:00Z"},"condition.PodScheduled":{"text":"True"},"condition.PodScheduled.since":{"time":"2026-09-29T09:00:00Z"},"condition.Ready":{"text":"True"},"condition.Ready.since":{"time":"2026-09-29T09:00:00Z"},"containers.started":{"time":"2026-09-29T09:00:00Z"},"created":{"time":"2026-09-29T09:00:00Z"},"deleting":{"bool":false},"labels":{"text":"app=filler"},"phase":{"text":"Running"},"qos":{"text":"Burstable"},"ready":{"bool":true},"ready.transition":{"time":"2026-09-29T09:00:00Z"},"start.time":{"time":"2026-09-29T09:00:00Z"}}}}
{"at":"2026-09-29T10:00:00Z","obs":{"kind":"related","source":"kubernetes","at":"2026-09-29T10:00:00Z","entity":{"kind":"pod","namespace":"batch","name":"filler-852d2550-a"},"relation":"calls"}}
{"at":"2026-09-29T10:00:00Z","obs":{"kind":"related","source":"kubernetes","at":"2026-09-29T10:00:00Z","entity":{"kind":"pod","namespace":"batch","name":"filler-852d2550-a"},"relation":"mounts"}}
{"at":"2026-09-29T10:00:00Z","obs":{"kind":"related","source":"kubernetes","at":"2026-09-29T10:00:00Z","entity":{"kind":"pod","namespace":"batch","name":"filler-852d2550-a"},"relation":"owned-by","targets":[{"kind":"replicaset","namespace":"batch","name":"filler-852d2550"}]}}
{"at":"2026-09-29T10:00:00Z","obs":{"kind":"related","source":"kubernetes","at":"2026-09-29T10:00:00Z","entity":{"kind":"pod","namespace":"batch","name":"filler-852d2550-a"},"relation":"pulls","targets":[{"kind":"image","name":"registry.example.com/filler:1.0"}]}}
{"at":"2026-09-29T10:00:00Z","obs":{"kind":"related","source":"kubernetes","at":"2026-09-29T10:00:00Z","entity":{"kind":"pod","namespace":"batch","name":"filler-852d2550-a"},"relation":"references"}}
{"at":"2026-09-29T10:00:00Z","obs":{"kind":"related","source":"kubernetes","at":"2026-09-29T10:00:00Z","entity":{"kind":"pod","namespace":"batch","name":"filler-852d2550-a"},"relation":"runs-on","targets":[{"kind":"node","name":"n1"}]}}
{"at":"2026-09-29T10:00:00Z","obs":{"kind":"observed","source":"kubernetes","at":"2026-09-29T10:00:00Z","entity":{"kind":"container","namespace":"batch","name":"filler-852d2550-a/app"},"attributes":{"cpu.request":{"number":2500},"image":{"text":"registry.example.com/filler:1.0"},"init":{"bool":false},"ready":{"bool":true},"restarts":{"number":0},"sidecar":{"bool":false},"started.at":{"time":"2026-09-29T09:00:00Z"},"state":{"text":"running"}}}}
{"at":"2026-09-29T10:00:00Z","obs":{"kind":"related","source":"kubernetes","at":"2026-09-29T10:00:00Z","entity":{"kind":"container","namespace":"batch","name":"filler-852d2550-a/app"},"relation":"part-of","targets":[{"kind":"pod","namespace":"batch","name":"filler-852d2550-a"}]}}
{"at":"2026-09-29T10:00:00Z","obs":{"kind":"related","source":"kubernetes","at":"2026-09-29T10:00:00Z","entity":{"kind":"container","namespace":"batch","name":"filler-852d2550-a/app"},"relation":"pulls","targets":[{"kind":"image","name":"registry.example.com/filler:1.0"}]}}
{"at":"2026-09-29T10:00:00Z","obs":{"kind":"observed","source":"kubernetes","at":"2026-09-29T10:00:00Z","entity":{"kind":"pod","namespace":"batch","name":"filler-852d2550-b"},"uid":"filler-852d2550-b","attributes":{"condition.ContainersReady":{"text":"True"},"condition.ContainersReady.since":{"time":"2026-09-29T09:00:00Z"},"condition.PodScheduled":{"text":"True"},"condition.PodScheduled.since":{"time":"2026-09-29T09:00:00Z"},"condition.Ready":{"text":"True"},"condition.Ready.since":{"time":"2026-09-29T09:00:00Z"},"containers.started":{"time":"2026-09-29T09:00:00Z"},"created":{"time":"2026-09-29T09:00:00Z"},"deleting":{"bool":false},"labels":{"text":"app=filler"},"phase":{"text":"Running"},"qos":{"text":"Burstable"},"ready":{"bool":true},"ready.transition":{"time":"2026-09-29T09:00:00Z"},"start.time":{"time":"2026-09-29T09:00:00Z"}}}}
{"at":"2026-09-29T10:00:00Z","obs":{"kind":"related","source":"kubernetes","at":"2026-09-29T10:00:00Z","entity":{"kind":"pod","namespace":"batch","name":"filler-852d2550-b"},"relation":"calls"}}
{"at":"2026-09-29T10:00:00Z","obs":{"kind":"related","source":"kubernetes","at":"2026-09-29T10:00:00Z","entity":{"kind":"pod","namespace":"batch","name":"filler-852d2550-b"},"relation":"mounts"}}
{"at":"2026-09-29T10:00:00Z","obs":{"kind":"related","source":"kubernetes","at":"2026-09-29T10:00:00Z","entity":{"kind":"pod","namespace":"batch","name":"filler-852d2550-b"},"relation":"owned-by","targets":[{"kind":"replicaset","namespace":"batch","name":"filler-852d2550"}]}}
{"at":"2026-09-29T10:00:00Z","obs":{"kind":"related","source":"kubernetes","at":"2026-09-29T10:00:00Z","entity":{"kind":"pod","namespace":"batch","name":"filler-852d2550-b"},"relation":"pulls","targets":[{"kind":"image","name":"registry.example.com/filler:1.0"}]}}
{"at":"2026-09-29T10:00:00Z","obs":{"kind":"related","source":"kubernetes","at":"2026-09-29T10:00:00Z","entity":{"kind":"pod","namespace":"batch","name":"filler-852d2550-b"},"relation":"references"}}
{"at":"2026-09-29T10:00:00Z","obs":{"kind":"related","source":"kubernetes","at":"2026-09-29T10:00:00Z","entity":{"kind":"pod","namespace":"batch","name":"filler-852d2550-b"},"relation":"runs-on","targets":[{"kind":"node","name":"n2"}]}}
{"at":"2026-09-29T10:00:00Z","obs":{"kind":"observed","source":"kubernetes","at":"2026-09-29T10:00:00Z","entity":{"kind":"container","namespace":"batch","name":"filler-852d2550-b/app"},"attributes":{"cpu.request":{"number":2500},"image":{"text":"registry.example.com/filler:1.0"},"init":{"bool":false},"ready":{"bool":true},"restarts":{"number":0},"sidecar":{"bool":false},"started.at":{"time":"2026-09-29T09:00:00Z"},"state":{"text":"running"}}}}
{"at":"2026-09-29T10:00:00Z","obs":{"kind":"related","source":"kubernetes","at":"2026-09-29T10:00:00Z","entity":{"kind":"container","namespace":"batch","name":"filler-852d2550-b/app"},"relation":"part-of","targets":[{"kind":"pod","namespace":"batch","name":"filler-852d2550-b"}]}}
{"at":"2026-09-29T10:00:00Z","obs":{"kind":"related","source":"kubernetes","at":"2026-09-29T10:00:00Z","entity":{"kind":"container","namespace":"batch","name":"filler-852d2550-b/app"},"relation":"pulls","targets":[{"kind":"image","name":"registry.example.com/filler:1.0"}]}}
{"at":"2026-09-29T10:00:00Z","obs":{"kind":"observed","source":"kubernetes","at":"2026-09-29T10:00:00Z","entity":{"kind":"pod","namespace":"batch","name":"filler-852d2550-c"},"uid":"filler-852d2550-c","attributes":{"condition.ContainersReady":{"text":"True"},"condition.ContainersReady.since":{"time":"2026-09-29T09:00:00Z"},"condition.PodScheduled":{"text":"True"},"condition.PodScheduled.since":{"time":"2026-09-29T09:00:00Z"},"condition.Ready":{"text":"True"},"condition.Ready.since":{"time":"2026-09-29T09:00:00Z"},"containers.started":{"time":"2026-09-29T09:00:00Z"},"created":{"time":"2026-09-29T09:00:00Z"},"deleting":{"bool":false},"labels":{"text":"app=filler"},"phase":{"text":"Running"},"qos":{"text":"Burstable"},"ready":{"bool":true},"ready.transition":{"time":"2026-09-29T09:00:00Z"},"start.time":{"time":"2026-09-29T09:00:00Z"}}}}
{"at":"2026-09-29T10:00:00Z","obs":{"kind":"related","source":"kubernetes","at":"2026-09-29T10:00:00Z","entity":{"kind":"pod","namespace":"batch","name":"filler-852d2550-c"},"relation":"calls"}}
{"at":"2026-09-29T10:00:00Z","obs":{"kind":"related","source":"kubernetes","at":"2026-09-29T10:00:00Z","entity":{"kind":"pod","namespace":"batch","name":"filler-852d2550-c"},"relation":"mounts"}}
{"at":"2026-09-29T10:00:00Z","obs":{"kind":"related","source":"kubernetes","at":"2026-09-29T10:00:00Z","entity":{"kind":"pod","namespace":"batch","name":"filler-852d2550-c"},"relation":"owned-by","targets":[{"kind":"replicaset","namespace":"batch","name":"filler-852d2550"}]}}
{"at":"2026-09-29T10:00:00Z","obs":{"kind":"related","source":"kubernetes","at":"2026-09-29T10:00:00Z","entity":{"kind":"pod","namespace":"batch","name":"filler-852d2550-c"},"relation":"pulls","targets":[{"kind":"image","name":"registry.example.com/filler:1.0"}]}}
{"at":"2026-09-29T10:00:00Z","obs":{"kind":"related","source":"kubernetes","at":"2026-09-29T10:00:00Z","entity":{"kind":"pod","namespace":"batch","name":"filler-852d2550-c"},"relation":"references"}}
{"at":"2026-09-29T10:00:00Z","obs":{"kind":"related","source":"kubernetes","at":"2026-09-29T10:00:00Z","entity":{"kind":"pod","namespace":"batch","name":"filler-852d2550-c"},"relation":"runs-on","targets":[{"kind":"node","name":"n3"}]}}
{"at":"2026-09-29T10:00:00Z","obs":{"kind":"observed","source":"kubernetes","at":"2026-09-29T10:00:00Z","entity":{"kind":"container","namespace":"batch","name":"filler-852d2550-c/app"},"attributes":{"cpu.request":{"number":2500},"image":{"text":"registry.example.com/filler:1.0"},"init":{"bool":false},"ready":{"bool":true},"restarts":{"number":0},"sidecar":{"bool":false},"started.at":{"time":"2026-09-29T09:00:00Z"},"state":{"text":"running"}}}}
{"at":"2026-09-29T10:00:00Z","obs":{"kind":"related","source":"kubernetes","at":"2026-09-29T10:00:00Z","entity":{"kind":"container","namespace":"batch","name":"filler-852d2550-c/app"},"relation":"part-of","targets":[{"kind":"pod","namespace":"batch","name":"filler-852d2550-c"}]}}
{"at":"2026-09-29T10:00:00Z","obs":{"kind":"related","source":"kubernetes","at":"2026-09-29T10:00:00Z","entity":{"kind":"container","namespace":"batch","name":"filler-852d2550-c/app"},"relation":"pulls","targets":[{"kind":"image","name":"registry.example.com/filler:1.0"}]}}
{"at":"2026-09-29T10:00:00Z","obs":{"kind":"observed","source":"kubernetes","at":"2026-09-29T10:00:00Z","entity":{"kind":"deployment","namespace":"analytics","name":"etl"},"uid":"8c7bd424c6f9b587","attributes":{"created":{"time":"2026-09-28T10:00:00Z"},"deleting":{"bool":false},"generation":{"number":2},"generation.observed":{"number":2},"replicas":{"number":1},"replicas.available":{"number":0},"replicas.ready":{"number":0},"replicas.unavailable":{"number":1},"replicas.updated":{"number":1},"template.hash":{"text":"0a0ee345595f"},"template.labels":{"text":"app=etl"}}}}
{"at":"2026-09-29T10:00:00Z","obs":{"kind":"related","source":"kubernetes","at":"2026-09-29T10:00:00Z","entity":{"kind":"deployment","namespace":"analytics","name":"etl"},"relation":"owned-by"}}
{"at":"2026-09-29T10:00:00Z","obs":{"kind":"related","source":"kubernetes","at":"2026-09-29T10:00:00Z","entity":{"kind":"deployment","namespace":"analytics","name":"etl"},"relation":"references"}}
{"at":"2026-09-29T10:00:00Z","obs":{"kind":"changed","source":"kubernetes","at":"2026-09-29T10:00:00Z","entity":{"kind":"deployment","namespace":"analytics","name":"etl"},"change":{"at":"2026-09-29T10:00:00Z","observed":"2026-09-29T10:00:00Z","revision":"generation 2","created":true}}}
{"at":"2026-09-29T10:00:00Z","obs":{"kind":"observed","source":"kubernetes","at":"2026-09-29T10:00:00Z","entity":{"kind":"replicaset","namespace":"analytics","name":"etl-081a5719"},"uid":"etl-081a5719","attributes":{"created":{"time":"2026-09-29T10:00:00Z"},"deleting":{"bool":false},"generation":{"number":0},"generation.observed":{"number":0},"replicas":{"number":1},"replicas.available":{"number":0},"replicas.ready":{"number":0},"template.hash":{"text":"0a0ee345595f"},"template.labels":{"text":"app=etl"}}}}
{"at":"2026-09-29T10:00:00Z","obs":{"kind":"related","source":"kubernetes","at":"2026-09-29T10:00:00Z","entity":{"kind":"replicaset","namespace":"analytics","name":"etl-081a5719"},"relation":"owned-by","targets":[{"kind":"deployment","namespace":"analytics","name":"etl"}]}}
{"at":"2026-09-29T10:00:00Z","obs":{"kind":"related","source":"kubernetes","at":"2026-09-29T10:00:00Z","entity":{"kind":"replicaset","namespace":"analytics","name":"etl-081a5719"},"relation":"references"}}
{"at":"2026-09-29T10:00:00Z","obs":{"kind":"changed","source":"kubernetes","at":"2026-09-29T10:00:00Z","entity":{"kind":"replicaset","namespace":"analytics","name":"etl-081a5719"},"change":{"at":"2026-09-29T10:00:00Z","observed":"2026-09-29T10:00:00Z","created":true}}}
{"at":"2026-09-29T10:00:00Z","obs":{"kind":"observed","source":"kubernetes","at":"2026-09-29T10:00:00Z","entity":{"kind":"pod","namespace":"analytics","name":"etl-081a5719-a"},"uid":"etl-081a5719-a","attributes":{"condition.PodScheduled":{"text":"False"},"condition.PodScheduled.message":{"text":"0/3 nodes are available: 3 Insufficient cpu. preemption: 0/3 nodes are available: 3 No preemption victims found for incoming pod."},"condition.PodScheduled.reason":{"text":"Unschedulable"},"condition.PodScheduled.since":{"time":"2026-09-29T10:00:00Z"},"created":{"time":"2026-09-29T10:00:00Z"},"deleting":{"bool":false},"labels":{"text":"app=etl"},"phase":{"text":"Pending"},"qos":{"text":"Burstable"}}}}
{"at":"2026-09-29T10:00:00Z","obs":{"kind":"related","source":"kubernetes","at":"2026-09-29T10:00:00Z","entity":{"kind":"pod","namespace":"analytics","name":"etl-081a5719-a"},"relation":"calls"}}
{"at":"2026-09-29T10:00:00Z","obs":{"kind":"related","source":"kubernetes","at":"2026-09-29T10:00:00Z","entity":{"kind":"pod","namespace":"analytics","name":"etl-081a5719-a"},"relation":"mounts"}}
{"at":"2026-09-29T10:00:00Z","obs":{"kind":"related","source":"kubernetes","at":"2026-09-29T10:00:00Z","entity":{"kind":"pod","namespace":"analytics","name":"etl-081a5719-a"},"relation":"owned-by","targets":[{"kind":"replicaset","namespace":"analytics","name":"etl-081a5719"}]}}
{"at":"2026-09-29T10:00:00Z","obs":{"kind":"related","source":"kubernetes","at":"2026-09-29T10:00:00Z","entity":{"kind":"pod","namespace":"analytics","name":"etl-081a5719-a"},"relation":"pulls","targets":[{"kind":"image","name":"registry.example.com/etl:4.1"}]}}
{"at":"2026-09-29T10:00:00Z","obs":{"kind":"related","source":"kubernetes","at":"2026-09-29T10:00:00Z","entity":{"kind":"pod","namespace":"analytics","name":"etl-081a5719-a"},"relation":"references"}}
{"at":"2026-09-29T10:00:00Z","obs":{"kind":"related","source":"kubernetes","at":"2026-09-29T10:00:00Z","entity":{"kind":"pod","namespace":"analytics","name":"etl-081a5719-a"},"relation":"runs-on"}}
{"at":"2026-09-29T10:00:00Z","obs":{"kind":"observed","source":"kubernetes","at":"2026-09-29T10:00:00Z","entity":{"kind":"container","namespace":"analytics","name":"etl-081a5719-a/app"},"attributes":{"cpu.request":{"number":3000},"image":{"text":"registry.example.com/etl:4.1"},"init":{"bool":false},"sidecar":{"bool":false}}}}
{"at":"2026-09-29T10:00:00Z","obs":{"kind":"related","source":"kubernetes","at":"2026-09-29T10:00:00Z","entity":{"kind":"container","namespace":"analytics","name":"etl-081a5719-a/app"},"relation":"part-of","targets":[{"kind":"pod","namespace":"analytics","name":"etl-081a5719-a"}]}}
{"at":"2026-09-29T10:00:00Z","obs":{"kind":"related","source":"kubernetes","at":"2026-09-29T10:00:00Z","entity":{"kind":"container","namespace":"analytics","name":"etl-081a5719-a/app"},"relation":"pulls","targets":[{"kind":"image","name":"registry.example.com/etl:4.1"}]}}
{"at":"2026-09-29T10:00:00Z","obs":{"kind":"changed","source":"kubernetes","at":"2026-09-29T10:00:00Z","entity":{"kind":"pod","namespace":"analytics","name":"etl-081a5719-a"},"change":{"at":"2026-09-29T10:00:00Z","observed":"2026-09-29T10:00:00Z","created":true}}}
{"at":"2026-09-29T10:01:00Z","obs":{"kind":"noted","source":"kubernetes","at":"2026-09-29T10:01:00Z","entity":{"kind":"pod","namespace":"analytics","name":"etl-081a5719-a"},"note":{"at":"2026-09-29T10:01:00Z","source":"default-scheduler","reason":"FailedScheduling","message":"0/3 nodes are available: 3 Insufficient cpu. preemption: 0/3 nodes are available: 3 No preemption victims found for incoming pod.","count":1,"warning":true}}}
{"at":"2026-09-29T10:02:00Z","obs":{"kind":"noted","source":"kubernetes","at":"2026-09-29T10:02:00Z","entity":{"kind":"pod","namespace":"analytics","name":"etl-081a5719-a"},"note":{"at":"2026-09-29T10:02:00Z","source":"default-scheduler","reason":"FailedScheduling","message":"0/3 nodes are available: 3 Insufficient cpu. preemption: 0/3 nodes are available: 3 No preemption victims found for incoming pod.","count":2,"warning":true}}}
{"at":"2026-09-29T10:03:00Z","obs":{"kind":"noted","source":"kubernetes","at":"2026-09-29T10:03:00Z","entity":{"kind":"pod","namespace":"analytics","name":"etl-081a5719-a"},"note":{"at":"2026-09-29T10:03:00Z","source":"default-scheduler","reason":"FailedScheduling","message":"0/3 nodes are available: 3 Insufficient cpu. preemption: 0/3 nodes are available: 3 No preemption victims found for incoming pod.","count":3,"warning":true}}}
{"at":"2026-09-29T10:04:00Z","obs":{"kind":"noted","source":"kubernetes","at":"2026-09-29T10:04:00Z","entity":{"kind":"pod","namespace":"analytics","name":"etl-081a5719-a"},"note":{"at":"2026-09-29T10:04:00Z","source":"default-scheduler","reason":"FailedScheduling","message":"0/3 nodes are available: 3 Insufficient cpu. preemption: 0/3 nodes are available: 3 No preemption victims found for incoming pod.","count":4,"warning":true}}}
{"at":"2026-09-29T10:05:00Z","obs":{"kind":"noted","source":"kubernetes","at":"2026-09-29T10:05:00Z","entity":{"kind":"pod","namespace":"analytics","name":"etl-081a5719-a"},"note":{"at":"2026-09-29T10:05:00Z","source":"default-scheduler","reason":"FailedScheduling","message":"0/3 nodes are available: 3 Insufficient cpu. preemption: 0/3 nodes are available: 3 No preemption victims found for incoming pod.","count":5,"warning":true}}}
{"at":"2026-09-29T10:06:00Z","obs":{"kind":"noted","source":"kubernetes","at":"2026-09-29T10:06:00Z","entity":{"kind":"pod","namespace":"analytics","name":"etl-081a5719-a"},"note":{"at":"2026-09-29T10:06:00Z","source":"default-scheduler","reason":"FailedScheduling","message":"0/3 nodes are available: 3 Insufficient cpu. preemption: 0/3 nodes are available: 3 No preemption victims found for incoming pod.","count":6,"warning":true}}}
