{"format":"kwatch-observations","version":1,"start":"2026-09-29T10:00:00Z"}
{"at":"2026-09-29T10:00:00Z","obs":{"kind":"observed","source":"kubernetes","at":"2026-09-29T10:00:00Z","entity":{"kind":"node","name":"t1"},"uid":"1b898f0ecf9cc9d3","attributes":{"condition.Ready":{"text":"True"},"condition.Ready.reason":{"text":"KubeletReady"},"condition.Ready.since":{"time":"2026-09-29T09:00:00Z"},"cpu.allocatable":{"number":4000},"created":{"time":"2026-09-28T10:00:00Z"},"deleting":{"bool":false},"instance.type":{"text":""},"kernel.version":{"text":""},"kubelet.version":{"text":""},"memory.allocatable":{"number":17179869184},"os":{"text":""},"ready":{"bool":true},"ready.transition":{"time":"2026-09-29T09:00:00Z"},"runtime.version":{"text":""},"taints":{"text":"dedicated=gpu:NoSchedule"},"unschedulable":{"bool":false}}}}
{"at":"2026-09-29T10:00:00Z","obs":{"kind":"related","source":"kubernetes","at":"2026-09-29T10:00:00Z","entity":{"kind":"node","name":"t1"},"relation":"part-of","targets":[{"kind":"zone","name":"zone-a"}]}}
{"at":"2026-09-29T10:00:00Z","obs":{"kind":"observed","source":"kubernetes","at":"2026-09-29T10:00:00Z","entity":{"kind":"node","name":"t2"},"uid":"f2ca88a937fde8e5","attributes":{"condition.Ready":{"text":"True"},"condition.Ready.reason":{"text":"KubeletReady"},"condition.Ready.since":{"time":"2026-09-29T09:00:00Z"},"cpu.allocatable":{"number":4000},"created":{"time":"2026-09-28T10:00:00Z"},"deleting":{"bool":false},"instance.type":{"text":""},"kernel.version":{"text":""},"kubelet.version":{"text":""},"memory.allocatable":{"number":17179869184},"os":{"text":""},"ready":{"bool":true},"ready.transition":{"time":"2026-09-29T09:00:00Z"},"runtime.version":{"text":""},"taints":{"text":"dedicated=gpu:NoSchedule"},"unschedulable":{"bool":false}}}}
{"at":"2026-09-29T10:00:00Z","obs":{"kind":"related","source":"kubernetes","at":"2026-09-29T10:00:00Z","entity":{"kind":"node","name":"t2"},"relation":"part-of","targets":[{"kind":"zone","name":"zone-a"}]}}
{"at":"2026-09-29T10:00:00Z","obs":{"kind":"observed","source":"kubernetes","at":"2026-09-29T10:00:00Z","entity":{"kind":"deployment","namespace":"analytics","name":"report"},"uid":"0fffde7dc1046338","attributes":{"created":{"time":"2026-09-28T10:00:00Z"},"deleting":{"bool":false},"generation":{"number":2},"generation.observed":{"number":2},"replicas":{"number":1},"replicas.available":{"number":0},"replicas.ready":{"number":0},"replicas.unavailable":{"number":1},"replicas.updated":{"number":1},"template.hash":{"text":"dee8de0e7ea1"},"template.labels":{"text":"app=report"}}}}
{"at":"2026-09-29T10:00:00Z","obs":{"kind":"related","source":"kubernetes","at":"2026-09-29T10:00:00Z","entity":{"kind":"deployment","namespace":"analytics","name":"report"},"relation":"owned-by"}}
{"at":"2026-09-29T10:00:00Z","obs":{"kind":"related","source":"kubernetes","at":"2026-09-29T10:00:00Z","entity":{"kind":"deployment","namespace":"analytics","name":"report"},"relation":"references"}}
{"at":"2026-09-29T10:00:00Z","obs":{"kind":"changed","source":"kubernetes","at":"2026-09-29T10:00:00Z","entity":{"kind":"deployment","namespace":"analytics","name":"report"},"change":{"at":"2026-09-29T10:00:00Z","observed":"2026-09-29T10:00:00Z","revision":"generation 2","created":true}}}
{"at":"2026-09-29T10:00:00Z","obs":{"kind":"observed","source":"kubernetes","at":"2026-09-29T10:00:00Z","entity":{"kind":"replicaset","namespace":"analytics","name":"report-25042d19"},"uid":"report-25042d19","attributes":{"created":{"time":"2026-09-29T10:00:00Z"},"deleting":{"bool":false},"generation":{"number":0},"generation.observed":{"number":0},"replicas":{"number":1},"replicas.available":{"number":0},"replicas.ready":{"number":0},"template.hash":{"text":"dee8de0e7ea1"},"template.labels":{"text":"app=report"}}}}
{"at":"2026-09-29T10:00:00Z","obs":{"kind":"related","source":"kubernetes","at":"2026-09-29T10:00:00Z","entity":{"kind":"replicaset","namespace":"analytics","name":"report-25042d19"},"relation":"owned-by","targets":[{"kind":"deployment","namespace":"analytics","name":"report"}]}}
{"at":"2026-09-29T10:00:00Z","obs":{"kind":"related","source":"kubernetes","at":"2026-09-29T10:00:00Z","entity":{"kind":"replicaset","namespace":"analytics","name":"report-25042d19"},"relation":"references"}}
{"at":"2026-09-29T10:00:00Z","obs":{"kind":"changed","source":"kubernetes","at":"2026-09-29T10:00:00Z","entity":{"kind":"replicaset","namespace":"analytics","name":"report-25042d19"},"change":{"at":"2026-09-29T10:00:00Z","observed":"2026-09-29T10:00:00Z","created":true}}}
{"at":"2026-09-29T10:00:00Z","obs":{"kind":"observed","source":"kubernetes","at":"2026-09-29T10:00:00Z","entity":{"kind":"pod","namespace":"analytics","name":"report-25042d19-a"},"uid":"report-25042d19-a","attributes":{"condition.PodScheduled":{"text":"False"},"condition.PodScheduled.message":{"text":"0/2 nodes are available: 2 node(s) had untolerated taint {dedicated: gpu}. preemption: 0/2 nodes are available: 2 Preemption is not helpful for scheduling."},"condition.PodScheduled.reason":{"text":"Unschedulable"},"condition.PodScheduled.since":{"time":"2026-09-29T10:00:00Z"},"created":{"time":"2026-09-29T10:00:00Z"},"deleting":{"bool":false},"labels":{"text":"app=report"},"phase":{"text":"Pending"},"qos":{"text":"Burstable"}}}}
{"at":"2026-09-29T10:00:00Z","obs":{"kind":"related","source":"kubernetes","at":"2026-09-29T10:00:00Z","entity":{"kind":"pod","namespace":"analytics","name":"report-25042d19-a"},"relation":"calls"}}
{"at":"2026-09-29T10:00:00Z","obs":{"kind":"related","source":"kubernetes","at":"2026-09-29T10:00:00Z","entity":{"kind":"pod","namespace":"analytics","name":"report-25042d19-a"},"relation":"mounts"}}
{"at":"2026-09-29T10:00:00Z","obs":{"kind":"related","source":"kubernetes","at":"2026-09-29T10:00:00Z","entity":{"kind":"pod","namespace":"analytics","name":"report-25042d19-a"},"relation":"owned-by","targets":[{"kind":"replicaset","namespace":"analytics","name":"report-25042d19"}]}}
{"at":"2026-09-29T10:00:00Z","obs":{"kind":"related","source":"kubernetes","at":"2026-09-29T10:00:00Z","entity":{"kind":"pod","namespace":"analytics","name":"report-25042d19-a"},"relation":"pulls","targets":[{"kind":"image","name":"registry.example.com/report:2.0"}]}}
{"at":"2026-09-29T10:00:00Z","obs":{"kind":"related","source":"kubernetes","at":"2026-09-29T10:00:00Z","entity":{"kind":"pod","namespace":"analytics","name":"report-25042d19-a"},"relation":"references"}}
{"at":"2026-09-29T10:00:00Z","obs":{"kind":"related","source":"kubernetes","at":"2026-09-29T10:00:00Z","entity":{"kind":"pod","namespace":"analytics","name":"report-25042d19-a"},"relation":"runs-on"}}
{"at":"2026-09-29T10:00:00Z","obs":{"kind":"observed","source":"kubernetes","at":"2026-09-29T10:00:00Z","entity":{"kind":"container","namespace":"analytics","name":"report-25042d19-a/app"},"attributes":{"cpu.request":{"number":500},"image":{"text":"registry.example.com/report:2.0"},"init":{"bool":false},"sidecar":{"bool":false}}}}
{"at":"2026-09-29T10:00:00Z","obs":{"kind":"related","source":"kubernetes","at":"2026-09-29T10:00:00Z","entity":{"kind":"container","namespace":"analytics","name":"report-25042d19-a/app"},"relation":"part-of","targets":[{"kind":"pod","namespace":"analytics","name":"report-25042d19-a"}]}}
{"at":"2026-09-29T10:00:00Z","obs":{"kind":"related","source":"kubernetes","at":"2026-09-29T10:00:00Z","entity":{"kind":"container","namespace":"analytics","name":"report-25042d19-a/app"},"relation":"pulls","targets":[{"kind":"image","name":"registry.example.com/report:2.0"}]}}
{"at":"2026-09-29T10:00:00Z","obs":{"kind":"changed","source":"kubernetes","at":"2026-09-29T10:00:00Z","entity":{"kind":"pod","namespace":"analytics","name":"report-25042d19-a"},"change":{"at":"2026-09-29T10:00:00Z","observed":"2026-09-29T10:00:00Z","created":true}}}
{"at":"2026-09-29T10:01:00Z","obs":{"kind":"noted","source":"kubernetes","at":"2026-09-29T10:01:00Z","entity":{"kind":"pod","namespace":"analytics","name":"report-25042d19-a"},"note":{"at":"2026-09-29T10:01:00Z","source":"default-scheduler","reason":"FailedScheduling","message":"0/2 nodes are available: 2 node(s) had untolerated taint {dedicated: gpu}. preemption: 0/2 nodes are available: 2 Preemption is not helpful for scheduling.","count":1,"warning":true}}}
{"at":"2026-09-29T10:02:00Z","obs":{"kind":"noted","source":"kubernetes","at":"2026-09-29T10:02:00Z","entity":{"kind":"pod","namespace":"analytics","name":"report-25042d19-a"},"note":{"at":"2026-09-29T10:02:00Z","source":"default-scheduler","reason":"FailedScheduling","message":"0/2 nodes are available: 2 node(s) had untolerated taint {dedicated: gpu}. preemption: 0/2 nodes are available: 2 Preemption is not helpful for scheduling.","count":2,"warning":true}}}
{"at":"2026-09-29T10:03:00Z","obs":{"kind":"noted","source":"kubernetes","at":"2026-09-29T10:03:00Z","entity":{"kind":"pod","namespace":"analytics","name":"report-25042d19-a"},"note":{"at":"2026-09-29T10:03:00Z","source":"default-scheduler","reason":"FailedScheduling","message":"0/2 nodes are available: 2 node(s) had untolerated taint {dedicated: gpu}. preemption: 0/2 nodes are available: 2 Preemption is not helpful for scheduling.","count":3,"warning":true}}}
{"at":"2026-09-29T10:04:00Z","obs":{"kind":"noted","source":"kubernetes","at":"2026-09-29T10:04:00Z","entity":{"kind":"pod","namespace":"analytics","name":"report-25042d19-a"},"note":{"at":"2026-09-29T10:04:00Z","source":"default-scheduler","reason":"FailedScheduling","message":"0/2 nodes are available: 2 node(s) had untolerated taint {dedicated: gpu}. preemption: 0/2 nodes are available: 2 Preemption is not helpful for scheduling.","count":4,"warning":true}}}
{"at":"2026-09-29T10:05:00Z","obs":{"kind":"noted","source":"kubernetes","at":"2026-09-29T10:05:00Z","entity":{"kind":"pod","namespace":"analytics","name":"report-25042d19-a"},"note":{"at":"2026-09-29T10:05:00Z","source":"default-scheduler","reason":"FailedScheduling","message":"0/2 nodes are available: 2 node(s) had untolerated taint {dedicated: gpu}. preemption: 0/2 nodes are available: 2 Preemption is not helpful for scheduling.","count":5,"warning":true}}}
{"at":"2026-09-29T10:06:00Z","obs":{"kind":"noted","source":"kubernetes","at":"2026-09-29T10:06:00Z","entity":{"kind":"pod","namespace":"analytics","name":"report-25042d19-a"},"note":{"at":"2026-09-29T10:06:00Z","source":"default-scheduler","reason":"FailedScheduling","message":"0/2 nodes are available: 2 node(s) had untolerated taint {dedicated: gpu}. preemption: 0/2 nodes are available: 2 Preemption is not helpful for scheduling.","count":6,"warning":true}}}
